Workbook

Sheet README
A1: 반도체 장비용 불소고무 가스켓: 배합비-물성 데이터셋 및 가우시안 프로세스 모델
A3: 목적
A4: 공개 특허의 실시예/비교예 표에서 원재료(고무) 및 부재료(필러, 가교제, 가교조제, 수산제 등)의 배합비(phr)와 물성(경도, 인장강도, 신율, 100% 모듈러스, 압축영구줄음률)을 추출하고, 가우시안 프로세스(GP) 회귀 + 베이지안 최적화(BO)로 물성 예측 모델을 구축한 결과를 담은 파일입니다.
A6: 시트 구성
A7: Sources : 데이터 출처 특허 목록 (특허번호, 출원인, 제목, URL, 수집 행수/모델 사용 행수 = COUNTIF 수식)
A8: Raw_Data : 특허에서 추출한 전체 원자료 (표 값을 그대로 전사, 단위만 MPa로 환산)
A9: Model_Data : 정제 규칙을 통과해 모델링에 사용한 데이터 (파생변수 total_filler_phr 은 SUM 수식)
A10: Stats : 물성별 데이터 수·평균·표준편차·최소·최대 (Model_Data 참조 수식)
A11: HP_Trials : 하이퍼파라미터 실험 전체 기록 (기준모델, 커널 스크리닝, BO 3회 반복, 강건성 재평가)
A12: Best_Models : 물성별 최종 선택 하이퍼파라미터와 교차검증/테스트/출처별 검증 성능
A13: Predictions : 개발셋 OOF 예측 및 테스트셋 예측 (예측 표준편차, 95% 구간, 잔차 수식 포함)
A14: BO_Recommend : 학습된 GP + 제약 기대개선(cEI)으로 제안한 차기 실험 배합 후보 (실험 검증 전 예측값)
... A27: 요약 수치
A28: 수집 원자료 행 수 | B28: =COUNTA(Raw_Data!A:A)-1
A29: 수집 출처(특허) 수 | B29: =COUNTA(Sources!A:A)-2
A30: 모델링 사용 행 수 | B30: =COUNTA(Model_Data!A:A)-1

Sheet Sources
A1: source_id | B1: assignee | C1: title | D1: url | E1: rows_collected | F1: rows_in_model
A2: CN106633544B | B2: Shanghai Rushi Sealing Technology Co., Ltd. (上海如实密封科技有限公司) | C2: Fluororubber material for high-temperature high-pressure resistant sealing element and preparation method thereof | D2: https://patents.google.com/patent/CN106633544B/en | E2: =COUNTIF(Raw_Data!$A:$A,A2) | F2: =COUNTIF(Model_Data!$B:$B,A2)
A3: EP4249550A1 | B3: Mitsubishi Cable Industries, Ltd. | C3: Fluorine rubber composition and rubber molded article formed using same | D3: https://patents.google.com/patent/EP4249550A1/en | E3: =COUNTIF(Raw_Data!$A:$A,A3) | F3: =COUNTIF(Model_Data!$B:$B,A3)
A4: KR100894110B1 | B4: M&E Co., Ltd. (주식회사 엠앤이) | C4: Perfluoro rubbers for semiconductor sealing with improved elongation | D4: https://patents.google.com/patent/KR100894110B1/en | E4: =COUNTIF(Raw_Data!$A:$A,A4) | F4: =COUNTIF(Model_Data!$B:$B,A4)
A5: KR101467101B1 | B5: M&E Co., Ltd. (주식회사 엠앤이) | C5: Compound for sealing (FFKM compound for semiconductor/LCD CVD equipment) | D5: https://patents.google.com/patent/KR101467101B1/en | E5: =COUNTIF(Raw_Data!$A:$A,A5) | F5: =COUNTIF(Model_Data!$B:$B,A5)
A6: KR102323568B1 | B6: Chung-Ang University Industry-Academic Cooperation Foundation (중앙대학교 산학협력단) | C6: Perfluoro elastomer composite with improved heat resistance, and method of fabricating the same | D6: https://patents.google.com/patent/KR102323568B1/en | E6: =COUNTIF(Raw_Data!$A:$A,A6) | F6: =COUNTIF(Model_Data!$B:$B,A6)
A7: KR102324534B1 | B7: SHPP Global Technologies B.V. | C7: Composite material comprising fluoroelastomer and polyimide, method for producing the composite material, and article comprising the composite material | D7: https://patents.google.com/patent/KR102324534B1/en | E7: =COUNTIF(Raw_Data!$A:$A,A7) | F7: =COUNTIF(Model_Data!$B:$B,A7)
A8: KR102400335B1 | B8: M&E Co., Ltd. (주식회사 엠앤이) | C8: Sealing material for semiconductor manufacturing apparatus with improved plasma resistance in oxygen-atmosphere and fluorine-atmosphere plasma processes | D8: https://patents.google.com/patent/KR102400335B1/en | E8: =COUNTIF(Raw_Data!$A:$A,A8) | F8: =COUNTIF(Model_Data!$B:$B,A8)
A9: KR102713660B1 | B9: Hansung Tech Co., Ltd. (한성테크 주식회사) | C9: Method for manufacturing perfluororubber and fluororubber composite with improved chemical resistance | D9: https://patents.google.com/patent/KR102713660B1/en | E9: =COUNTIF(Raw_Data!$A:$A,A9) | F9: =COUNTIF(Model_Data!$B:$B,A9)
A10: KR102796110B1 | B10: DYFLEX Co., Ltd. (디와이플렉스 주식회사) | C10: Fluororubber-based composition for sealing | D10: https://patents.google.com/patent/KR102796110B1/en | E10: =COUNTIF(Raw_Data!$A:$A,A10) | F10: =COUNTIF(Model_Data!$B:$B,A10)
A11: KR20130014651A | B11: Pyung Hwa Oil Seal Industry Co., Ltd. (평화오일씰공업주식회사) | C11: Rubber composition of FKM oil seal with improved wear resistance | D11: https://patents.google.com/patent/KR20130014651A/en | E11: =COUNTIF(Raw_Data!$A:$A,A11) | F11: =COUNTIF(Model_Data!$B:$B,A11)
A12: US10723872B2 | B12: Nichias Corporation | C12: Crosslinkable elastomer composition, molded article, seal member, plasma treatment apparatus and semiconductor manufacturing apparatus including said seal member, and agent for decreasing hardness of molded article, method for producing molded article | D12: https://patents.google.com/patent/US10723872B2/en | E12: =COUNTIF(Raw_Data!$A:$A,A12) | F12: =COUNTIF(Model_Data!$B:$B,A12)
A13: US11072700B2 | B13: Daikin Industries, Ltd. | C13: Composition comprising fluoropolymer and molded article | D13: https://patents.google.com/patent/US11072700B2/en | E13: =COUNTIF(Raw_Data!$A:$A,A13) | F13: =COUNTIF(Model_Data!$B:$B,A13)
... A41: US8367776B2 | B41: Daikin Industries Ltd; Greene Tweed of Delaware Inc | C41: Perfluoroelastomer compositions and methods of preparing same | D41: https://patents.google.com/patent/US8367776B2/en | E41: =COUNTIF(Raw_Data!$A:$A,A41) | F41: =COUNTIF(Model_Data!$B:$B,A41)
A42: 합계 | E42: =SUM(E2:E41) | F42: =SUM(F2:F41)

Sheet Raw_Data
A1: source_id | B1: source_type | C1: assignee | D1: title | E1: url | F1: example_label | G1: polymer_type | H1: polymer_grade | I1: cure_system | J1: polymer_phr | K1: carbon_black_phr | L1: silica_phr | M1: alumina_phr | N1: barium_sulfate_phr | O1: titanium_oxide_phr | P1: fluororesin_phr | Q1: other_inorganic_filler_phr | R1: organic_additive_phr | S1: coagent_phr | T1: peroxide_phr | U1: nitrile_curative_phr | V1: other_curative_phr | W1: acid_acceptor_phr | X1: processing_aid_phr | Y1: other_ingredients_note | Z1: hardness_shoreA | AA1: tensile_MPa | AB1: elongation_pct | AC1: m100_MPa | AD1: compression_set_pct | AE1: cs_condition | AF1: plasma_weight_loss_pct | AG1: plasma_condition | AH1: units_original | AI1: extraction_notes
A2: US7678858B2 | B2: patent | C2: Daikin Industries, Ltd. | D2: Fluorine-containing elastomer composition excellent in plasma-aging prevention effect and shaped article made thereof | E2: https://patents.google.com/patent/US7678858B2/en | F2: Example 1 | G2: FFKM | H2: DAI-EL PERFLO GA-105 (TFE/perfluoro(alkyl vinyl ether), iodine cure site) | I2: peroxide | J2: 100 | K2: 0 | L2: 0 | M2: 15 | N2: 0 | O2: 0 | P2: 0 | Q2: 0 | R2: 2 | S2: 2 | T2: 1 | U2: 0 | V2: 0 | W2: 0 | X2: 0 | Y2: CROMOPHTAL Yellow 3RLP (isoindolinone pigment) 2; Al2O3 (0.02 um, 80 m2/g) 15; TAIC 2; PERHEXA 25B 1 | Z2: 78 | AA2: 24.52 | AB2: 170 | AC2: 9.02 | AD2: 21 | AE2: 200C x 70h, 25% compression, P-24 O-ring (JIS K6301) | AF2: 0.69 | AG2: O2 plasma, ICP high-density plasma device SAMCO RIE-101iPH, P-24 O-ring | AH2: M100 and tensile in kgf/cm2 (x0.0980665 -> MPa) | AI2: Tables 1 and 3. CF4 plasma weight loss 0.72%. Cure: press 160C x 7 min + oven 180C x 4 h.
A3: US7678858B2 | B3: patent | C3: Daikin Industries, Ltd. | D3: Fluorine-containing elastomer composition excellent in plasma-aging prevention effect and shaped article made thereof | E3: https://patents.google.com/patent/US7678858B2/en | F3: Example 2 | G3: FFKM | H3: DAI-EL PERFLO GA-105 (TFE/perfluoro(alkyl vinyl ether), iodine cure site) | I3: peroxide | J3: 100 | K3: 0 | L3: 0 | M3: 15 | N3: 0 | O3: 0 | P3: 0 | Q3: 0 | R3: 2 | S3: 2 | T3: 1 | U3: 0 | V3: 0 | W3: 0 | X3: 0 | Y3: CROMOPHTAL Red 2020 (quinacridone pigment) 2; Al2O3 (0.02 um, 80 m2/g) 15; TAIC 2; PERHEXA 25B 1 | Z3: 79 | AA3: 26.18 | AB3: 170 | AC3: 9.32 | AD3: 22 | AE3: 200C x 70h, 25% compression, P-24 O-ring (JIS K6301) | AF3: 0.7 | AG3: O2 plasma, ICP high-density plasma device SAMCO RIE-101iPH, P-24 O-ring | AH3: M100 and tensile in kgf/cm2 (x0.0980665 -> MPa) | AI3: Tables 1 and 3. CF4 plasma weight loss 0.76%. Cure: press 160C x 7 min + oven 180C x 4 h.
A4: US7678858B2 | B4: patent | C4: Daikin Industries, Ltd. | D4: Fluorine-containing elastomer composition excellent in plasma-aging prevention effect and shaped article made thereof | E4: https://patents.google.com/patent/US7678858B2/en | F4: Example 3 | G4: FFKM | H4: DAI-EL PERFLO GA-105 (TFE/perfluoro(alkyl vinyl ether), iodine cure site) | I4: peroxide | J4: 100 | K4: 0 | L4: 0 | M4: 15 | N4: 0 | O4: 0 | P4: 0 | Q4: 0 | R4: 2 | S4: 2 | T4: 1 | U4: 0 | V4: 0 | W4: 0 | X4: 0 | Y4: CROMOPHTAL Red 2030 (diketopyrrolopyrrole pigment) 2; Al2O3 (0.02 um, 80 m2/g) 15; TAIC 2; PERHEXA 25B 1 | Z4: 78 | AA4: 24.91 | AB4: 170 | AC4: 9.12 | AD4: 21 | AE4: 200C x 70h, 25% compression, P-24 O-ring (JIS K6301) | AF4: 0.71 | AG4: O2 plasma, ICP high-density plasma device SAMCO RIE-101iPH, P-24 O-ring | AH4: M100 and tensile in kgf/cm2 (x0.0980665 -> MPa) | AI4: Tables 1 and 3. CF4 plasma weight loss 0.74%. Cure: press 160C x 7 min + oven 180C x 4 h.
A5: US7678858B2 | B5: patent | C5: Daikin Industries, Ltd. | D5: Fluorine-containing elastomer composition excellent in plasma-aging prevention effect and shaped article made thereof | E5: https://patents.google.com/patent/US7678858B2/en | F5: Example 4 | G5: FFKM | H5: DAI-EL PERFLO GA-105 (TFE/perfluoro(alkyl vinyl ether), iodine cure site) | I5: peroxide | J5: 100 | K5: 0 | L5: 0 | M5: 15 | N5: 0 | O5: 0 | P5: 0 | Q5: 0 | R5: 2 | S5: 2 | T5: 1 | U5: 0 | V5: 0 | W5: 0 | X5: 0 | Y5: CROMOPHTAL Magenta P (quinacridone pigment) 2; Al2O3 (0.02 um, 80 m2/g) 15; TAIC 2; PERHEXA 25B 1 | Z5: 79 | AA5: 23.54 | AB5: 170 | AC5: 9.32 | AD5: 21 | AE5: 200C x 70h, 25% compression, P-24 O-ring (JIS K6301) | AF5: 0.67 | AG5: O2 plasma, ICP high-density plasma device SAMCO RIE-101iPH, P-24 O-ring | AH5: M100 and tensile in kgf/cm2 (x0.0980665 -> MPa) | AI5: Tables 1 and 3. CF4 plasma weight loss 0.77%. Cure: press 160C x 7 min + oven 180C x 4 h.
A6: US7678858B2 | B6: patent | C6: Daikin Industries, Ltd. | D6: Fluorine-containing elastomer composition excellent in plasma-aging prevention effect and shaped article made thereof | E6: https://patents.google.com/patent/US7678858B2/en | F6: Example 5 | G6: FFKM | H6: DAI-EL PERFLO GA-105 (TFE/perfluoro(alkyl vinyl ether), iodine cure site) | I6: peroxide | J6: 100 | K6: 0 | L6: 0 | M6: 15 | N6: 0 | O6: 0 | P6: 0 | Q6: 0 | R6: 2 | S6: 2 | T6: 1 | U6: 0 | V6: 0 | W6: 0 | X6: 0 | Y6: CROMOPHTAL Blue A3R (anthraquinone pigment) 2; Al2O3 (0.02 um, 80 m2/g) 15; TAIC 2; PERHEXA 25B 1 | Z6: 78 | AA6: 23.24 | AB6: 170 | AC6: 9.12 | AD6: 23 | AE6: 200C x 70h, 25% compression, P-24 O-ring (JIS K6301) | AF6: 0.73 | AG6: O2 plasma, ICP high-density plasma device SAMCO RIE-101iPH, P-24 O-ring | AH6: M100 and tensile in kgf/cm2 (x0.0980665 -> MPa) | AI6: Tables 1 and 3. CF4 plasma weight loss 0.74%. Cure: press 160C x 7 min + oven 180C x 4 h.
A7: US7678858B2 | B7: patent | C7: Daikin Industries, Ltd. | D7: Fluorine-containing elastomer composition excellent in plasma-aging prevention effect and shaped article made thereof | E7: https://patents.google.com/patent/US7678858B2/en | F7: Example 6 | G7: FFKM | H7: DAI-EL PERFLO GA-105 (TFE/perfluoro(alkyl vinyl ether), iodine cure site) | I7: peroxide | J7: 100 | K7: 0 | L7: 0 | M7: 15 | N7: 0 | O7: 0 | P7: 0 | Q7: 0 | R7: 2 | S7: 2 | T7: 1 | U7: 0 | V7: 0 | W7: 0 | X7: 0 | Y7: Antage RD (amine antioxidant) 2; Al2O3 (0.02 um, 80 m2/g) 15; TAIC 2; PERHEXA 25B 1 | Z7: 78 | AA7: 23.63 | AB7: 170 | AC7: 8.34 | AD7: 28 | AE7: 200C x 70h, 25% compression, P-24 O-ring (JIS K6301) | AF7: 0.69 | AG7: O2 plasma, ICP high-density plasma device SAMCO RIE-101iPH, P-24 O-ring | AH7: M100 and tensile in kgf/cm2 (x0.0980665 -> MPa) | AI7: Tables 1 and 3. CF4 plasma weight loss 0.59%. Cure: press 160C x 7 min + oven 180C x 4 h.
A8: US7678858B2 | B8: patent | C8: Daikin Industries, Ltd. | D8: Fluorine-containing elastomer composition excellent in plasma-aging prevention effect and shaped article made thereof | E8: https://patents.google.com/patent/US7678858B2/en | F8: Example 7 | G8: FFKM | H8: DAI-EL PERFLO GA-105 (TFE/perfluoro(alkyl vinyl ether), iodine cure site) | I8: peroxide | J8: 100 | K8: 0 | L8: 0 | M8: 15 | N8: 0 | O8: 0 | P8: 0 | Q8: 0 | R8: 2 | S8: 2 | T8: 1 | U8: 0 | V8: 0 | W8: 0 | X8: 0 | Y8: Antage W-300 (phenol antioxidant) 2; Al2O3 (0.02 um, 80 m2/g) 15; TAIC 2; PERHEXA 25B 1 | Z8: 79 | AA8: 25.11 | AB8: 200 | AC8: 5.98 | AD8: 48 | AE8: 200C x 70h, 25% compression, P-24 O-ring (JIS K6301) | AF8: 0.7 | AG8: O2 plasma, ICP high-density plasma device SAMCO RIE-101iPH, P-24 O-ring | AH8: M100 and tensile in kgf/cm2 (x0.0980665 -> MPa) | AI8: Tables 1 and 3. CF4 plasma weight loss 0.78%. Cure: press 160C x 7 min + oven 180C x 4 h.
A9: US7678858B2 | B9: patent | C9: Daikin Industries, Ltd. | D9: Fluorine-containing elastomer composition excellent in plasma-aging prevention effect and shaped article made thereof | E9: https://patents.google.com/patent/US7678858B2/en | F9: Example 8 | G9: FFKM | H9: DAI-EL PERFLO GA-105 (TFE/perfluoro(alkyl vinyl ether), iodine cure site) | I9: peroxide | J9: 100 | K9: 0 | L9: 0 | M9: 15 | N9: 0 | O9: 0 | P9: 0 | Q9: 0 | R9: 2 | S9: 2 | T9: 1 | U9: 0 | V9: 0 | W9: 0 | X9: 0 | Y9: Antage Crystal (phenol antioxidant) 2; Al2O3 (0.02 um, 80 m2/g) 15; TAIC 2; PERHEXA 25B 1 | Z9: 78 | AA9: 24.71 | AB9: 190 | AC9: 6.96 | AD9: 45 | AE9: 200C x 70h, 25% compression, P-24 O-ring (JIS K6301) | AF9: 0.67 | AG9: O2 plasma, ICP high-density plasma device SAMCO RIE-101iPH, P-24 O-ring | AH9: M100 and tensile in kgf/cm2 (x0.0980665 -> MPa) | AI9: Tables 1 and 3. CF4 plasma weight loss 0.73%. Cure: press 160C x 7 min + oven 180C x 4 h.
A10: US7678858B2 | B10: patent | C10: Daikin Industries, Ltd. | D10: Fluorine-containing elastomer composition excellent in plasma-aging prevention effect and shaped article made thereof | E10: https://patents.google.com/patent/US7678858B2/en | F10: Example 9 | G10: FFKM | H10: DAI-EL PERFLO GA-105 (TFE/perfluoro(alkyl vinyl ether), iodine cure site) | I10: peroxide | J10: 100 | K10: 0 | L10: 0 | M10: 15 | N10: 0 | O10: 0 | P10: 0 | Q10: 0 | R10: 2 | S10: 2 | T10: 1 | U10: 0 | V10: 0 | W10: 0 | X10: 0 | Y10: Antage MB (amine/sulfur antioxidant) 2; Al2O3 (0.02 um, 80 m2/g) 15; TAIC 2; PERHEXA 25B 1 | Z10: 80 | AA10: 23.14 | AB10: 170 | AC10: 8.92 | AD10: 28 | AE10: 200C x 70h, 25% compression, P-24 O-ring (JIS K6301) | AF10: 0.71 | AG10: O2 plasma, ICP high-density plasma device SAMCO RIE-101iPH, P-24 O-ring | AH10: M100 and tensile in kgf/cm2 (x0.0980665 -> MPa) | AI10: Tables 1 and 3. CF4 plasma weight loss 0.67%. Cure: press 160C x 7 min + oven 180C x 4 h.
A11: US7678858B2 | B11: patent | C11: Daikin Industries, Ltd. | D11: Fluorine-containing elastomer composition excellent in plasma-aging prevention effect and shaped article made thereof | E11: https://patents.google.com/patent/US7678858B2/en | F11: Comparative Example 1 | G11: FFKM | H11: DAI-EL PERFLO GA-105 (TFE/perfluoro(alkyl vinyl ether), iodine cure site) | I11: peroxide | J11: 100 | K11: 0 | L11: 0 | M11: 15 | N11: 0 | O11: 0 | P11: 0 | Q11: 0 | R11: 0 | S11: 2 | T11: 1 | U11: 0 | V11: 0 | W11: 0 | X11: 0 | Y11: no plasma anti-aging compound; Al2O3 (0.02 um, 80 m2/g) 15; TAIC 2; PERHEXA 25B 1 | Z11: 75 | AA11: 23.83 | AB11: 160 | AC11: 8.83 | AD11: 21 | AE11: 200C x 70h, 25% compression, P-24 O-ring (JIS K6301) | AF11: 0.78 | AG11: O2 plasma, ICP high-density plasma device SAMCO RIE-101iPH, P-24 O-ring | AH11: M100 and tensile in kgf/cm2 (x0.0980665 -> MPa) | AI11: Tables 1 and 3. CF4 plasma weight loss 0.82%. Cure: press 160C x 7 min + oven 180C x 4 h.
A12: US7678858B2 | B12: patent | C12: Daikin Industries, Ltd. | D12: Fluorine-containing elastomer composition excellent in plasma-aging prevention effect and shaped article made thereof | E12: https://patents.google.com/patent/US7678858B2/en | F12: Example 10 | G12: FFKM | H12: DAI-EL PERFLO GA-105 (TFE/perfluoro(alkyl vinyl ether), iodine cure site) | I12: peroxide | J12: 100 | K12: 0 | L12: 0 | M12: 0 | N12: 0 | O12: 0 | P12: 0 | Q12: 0 | R12: 15 | S12: 2 | T12: 1 | U12: 0 | V12: 0 | W12: 0 | X12: 0 | Y12: CROMOPHTAL Red 2020 15; no filler; TAIC 2; PERHEXA 25B 1 | Z12: 82 | AA12: 16.18 | AB12: 190 | AC12: 7.16 | AD12: 17 | AE12: 200C x 70h, 25% compression, P-24 O-ring (JIS K6301) | AF12: 3.49 | AG12: O2 plasma, ICP high-density plasma device SAMCO RIE-101iPH, P-24 O-ring | AH12: M100 and tensile in kgf/cm2 (x0.0980665 -> MPa) | AI12: Tables 2 and 4 (Example 10 has no filler per text). CF4 plasma weight loss 2.01%.
A13: US7678858B2 | B13: patent | C13: Daikin Industries, Ltd. | D13: Fluorine-containing elastomer composition excellent in plasma-aging prevention effect and shaped article made thereof | E13: https://patents.google.com/patent/US7678858B2/en | F13: Example 11 | G13: FFKM | H13: DAI-EL PERFLO GA-105 (TFE/perfluoro(alkyl vinyl ether), iodine cure site) | I13: peroxide | J13: 100 | K13: 0 | L13: 0 | M13: 15 | N13: 0 | O13: 0 | P13: 0 | Q13: 0 | R13: 15 | S13: 2 | T13: 1 | U13: 0 | V13: 0 | W13: 0 | X13: 0 | Y13: CROMOPHTAL Red 2020 15; Al2O3 15; TAIC 2; PERHEXA 25B 1 | Z13: 89 | AA13: 19.71 | AB13: 140 | AC13: 13.73 | AD13: 33 | AE13: 200C x 70h, 25% compression, P-24 O-ring (JIS K6301) | AF13: 0.65 | AG13: O2 plasma, ICP high-density plasma device SAMCO RIE-101iPH, P-24 O-ring | AH13: M100 and tensile in kgf/cm2 (x0.0980665 -> MPa) | AI13: Tables 2 and 4 (Example 10 has no filler per text). CF4 plasma weight loss 0.7%.
... A29: US6803402B2 | B29: patent | C29: Daikin Industries, Ltd. | D29: Elastomer molded article and crosslinkable fluorine-containing elastomer composition for semi-conductor production apparatuses | E29: https://patents.google.com/patent/US6803402B2/en | F29: Comparative Example 3 | G29: FFKM | H29: TFE/perfluoro(methyl vinyl ether) copolymer elastomer | I29: peroxide | J29: 100 | K29: 0 | L29: 0 | M29: 0 | N29: 0 | O29: 10 | P29: 0 | Q29: 0 | R29: 0 | S29: 3 | T29: 1 | U29: 0 | V29: 0 | W29: 0 | X29: 0 | Y29: Filler 5: TiO2 P-25 (0.021 um) 10; TAIC 3; PERHEXA 2.5B 1 | Z29: 59 | AA29: 19.71 | AB29: 153 | AC29: 5.88 | AD29: 20 | AE29: 200C x 70h, 25% compression, AS-568A-214 O-ring (JIS K6301) | AF29: 0.35 | AG29: O2 plasma 3 h, Samco PX-1000 RIE, 200 sccm, 400 W, 13.56 MHz, cleaned AS-568A-214 O-ring | AH29: M100 and tensile reported as 'kg.f' (taken as kgf/cm2, x0.0980665 -> MPa); hardness JIS A | AI29: Table 2. Table rows read 'Crosslinking agent 3 / Crosslinking aid 1'; Example 1 text states 1.0 g PERHEXA 2.5B and 3.0 g TAIC per 100 g polymer, used here. Plasma value from Table 3 (Comparative Example 6 = O-ring of Comparative Example 3, reported as weight change -0.35% after 3 h O2 plasma). Cure: press 160C x 10 min + oven 180C x 4 h.
A30: US8173727B2 | B30: patent | C30: Daikin Industries, Ltd. | D30: Crosslinkable elastomer composition and molded article using the same | E30: https://patents.google.com/patent/US8173727B2/en | F30: Example 1 | G30: FFKM | H30: TFE/PMVE copolymer (67/33 mol%) | I30: peroxide | J30: 100 | K30: 0 | L30: 0 | M30: 0 | N30: 0 | O30: 0 | P30: 0 | Q30: 0 | R30: 15 | S30: 2 | T30: 1 | U30: 0 | V30: 0 | W30: 0 | X30: 0 | Y30: polyimide UIP-S pulverized (~2 m2/g) 15; Perhexa 25B 1; TAIC 2 | Z30: 80 | AA30: 15.69 | AB30: 170 | AC30: 9.81 | AF30: 0.2 | AG30: high-density F radical (NF3/Ar 1/1 SLM, 5 torr, ASTRON generator), 200C, 2 h | AH30: M100 and tensile in kg/cm2 (x0.0980665 -> MPa) | AI30: Formulation from text (polymer/Perhexa 25B/TAIC/filler = 100/1/2/15); props Table 5, F-radical Table 4. O3 water exposure weight loss 2.8%. No compression set reported. Cure: press 160C x 10 min + oven 180C x 4 h.
A31: US8173727B2 | B31: patent | C31: Daikin Industries, Ltd. | D31: Crosslinkable elastomer composition and molded article using the same | E31: https://patents.google.com/patent/US8173727B2/en | F31: Example 2 | G31: FFKM | H31: TFE/PMVE copolymer (67/33 mol%) | I31: peroxide | J31: 100 | K31: 0 | L31: 0 | M31: 0 | N31: 0 | O31: 0 | P31: 0 | Q31: 0 | R31: 15 | S31: 2 | T31: 1 | U31: 0 | V31: 0 | W31: 0 | X31: 0 | Y31: polyimide UIP-S pulverized (~5 m2/g) 15; Perhexa 25B 1; TAIC 2 | Z31: 80 | AA31: 16.67 | AB31: 160 | AC31: 12.75 | AF31: 0.2 | AG31: high-density F radical (NF3/Ar 1/1 SLM, 5 torr, ASTRON generator), 200C, 2 h | AH31: M100 and tensile in kg/cm2 (x0.0980665 -> MPa) | AI31: Formulation from text (polymer/Perhexa 25B/TAIC/filler = 100/1/2/15); props Table 5, F-radical Table 4. O3 water exposure weight loss 2.9%. No compression set reported. Cure: press 160C x 10 min + oven 180C x 4 h.
A32: US8173727B2 | B32: patent | C32: Daikin Industries, Ltd. | D32: Crosslinkable elastomer composition and molded article using the same | E32: https://patents.google.com/patent/US8173727B2/en | F32: Example 3 | G32: FFKM | H32: TFE/PMVE copolymer (67/33 mol%) | I32: peroxide | J32: 100 | K32: 0 | L32: 0 | M32: 0 | N32: 0 | O32: 0 | P32: 0 | Q32: 0 | R32: 15 | S32: 2 | T32: 1 | U32: 0 | V32: 0 | W32: 0 | X32: 0 | Y32: polyimide UIP-S pulverized (~10 m2/g) 15; Perhexa 25B 1; TAIC 2 | Z32: 81 | AA32: 18.14 | AB32: 140 | AC32: 15.2 | AF32: 0.2 | AG32: high-density F radical (NF3/Ar 1/1 SLM, 5 torr, ASTRON generator), 200C, 2 h | AH32: M100 and tensile in kg/cm2 (x0.0980665 -> MPa) | AI32: Formulation from text (polymer/Perhexa 25B/TAIC/filler = 100/1/2/15); props Table 5, F-radical Table 4. O3 water exposure weight loss 2.8%. No compression set reported. Cure: press 160C x 10 min + oven 180C x 4 h.
A33: US8173727B2 | B33: patent | C33: Daikin Industries, Ltd. | D33: Crosslinkable elastomer composition and molded article using the same | E33: https://patents.google.com/patent/US8173727B2/en | F33: Example 4 | G33: FFKM | H33: TFE/PMVE copolymer (67/33 mol%) | I33: peroxide | J33: 100 | K33: 0 | L33: 0 | M33: 0 | N33: 0 | O33: 0 | P33: 0 | Q33: 0 | R33: 15 | S33: 2 | T33: 1 | U33: 0 | V33: 0 | W33: 0 | X33: 0 | Y33: polyimide UIP-S pulverized (~15 m2/g) 15; Perhexa 25B 1; TAIC 2 | Z33: 81 | AA33: 19.12 | AB33: 120 | AC33: 16.18 | AF33: 0.2 | AG33: high-density F radical (NF3/Ar 1/1 SLM, 5 torr, ASTRON generator), 200C, 2 h | AH33: M100 and tensile in kg/cm2 (x0.0980665 -> MPa) | AI33: Formulation from text (polymer/Perhexa 25B/TAIC/filler = 100/1/2/15); props Table 5, F-radical Table 4. O3 water exposure weight loss 2.7%. No compression set reported. Cure: press 160C x 10 min + oven 180C x 4 h.
A34: US8173727B2 | B34: patent | C34: Daikin Industries, Ltd. | D34: Crosslinkable elastomer composition and molded article using the same | E34: https://patents.google.com/patent/US8173727B2/en | F34: Example 5 | G34: FFKM | H34: TFE/PMVE copolymer (67/33 mol%) | I34: peroxide | J34: 100 | K34: 0 | L34: 0 | M34: 0 | N34: 0 | O34: 0 | P34: 0 | Q34: 0 | R34: 15 | S34: 2 | T34: 1 | U34: 0 | V34: 0 | W34: 0 | X34: 0 | Y34: polyimide UIP-S not pulverized (~0.6 m2/g, 7 um) 15; Perhexa 25B 1; TAIC 2 | Z34: 79 | AA34: 10.79 | AB34: 190 | AC34: 5.88 | AF34: 0.2 | AG34: high-density F radical (NF3/Ar 1/1 SLM, 5 torr, ASTRON generator), 200C, 2 h | AH34: M100 and tensile in kg/cm2 (x0.0980665 -> MPa) | AI34: Formulation from text (polymer/Perhexa 25B/TAIC/filler = 100/1/2/15); props Table 5, F-radical Table 4. O3 water exposure weight loss 2.8%. No compression set reported. Cure: press 160C x 10 min + oven 180C x 4 h.
A35: US8173727B2 | B35: patent | C35: Daikin Industries, Ltd. | D35: Crosslinkable elastomer composition and molded article using the same | E35: https://patents.google.com/patent/US8173727B2/en | F35: Example 6 | G35: FFKM | H35: TFE/PMVE copolymer (67/33 mol%) | I35: peroxide | J35: 100 | K35: 0 | L35: 0 | M35: 15 | N35: 0 | O35: 0 | P35: 0 | Q35: 0 | R35: 0 | S35: 2 | T35: 1 | U35: 0 | V35: 0 | W35: 0 | X35: 0 | Y35: theta-alumina AKP-G008 15; Perhexa 25B 1; TAIC 2 | Z35: 75 | AA35: 23.54 | AB35: 160 | AC35: 9.81 | AF35: 6.9 | AG35: high-density F radical (NF3/Ar 1/1 SLM, 5 torr, ASTRON generator), 200C, 2 h | AH35: M100 and tensile in kg/cm2 (x0.0980665 -> MPa) | AI35: Formulation from text (polymer/Perhexa 25B/TAIC/filler = 100/1/2/15); props Table 5, F-radical Table 4. O3 water exposure weight loss 2.6%. No compression set reported. Cure: press 160C x 10 min + oven 180C x 4 h.
A36: US8173727B2 | B36: patent | C36: Daikin Industries, Ltd. | D36: Crosslinkable elastomer composition and molded article using the same | E36: https://patents.google.com/patent/US8173727B2/en | F36: Example 7 | G36: FFKM | H36: TFE/PMVE copolymer (67/33 mol%) | I36: peroxide | J36: 100 | K36: 15 | L36: 0 | M36: 0 | N36: 0 | O36: 0 | P36: 0 | Q36: 0 | R36: 0 | S36: 2 | T36: 1 | U36: 0 | V36: 0 | W36: 0 | X36: 0 | Y36: carbon black N-990 15; Perhexa 25B 1; TAIC 2 | Z36: 80 | AA36: 19.61 | AB36: 180 | AC36: 9.81 | AF36: 0.3 | AG36: high-density F radical (NF3/Ar 1/1 SLM, 5 torr, ASTRON generator), 200C, 2 h | AH36: M100 and tensile in kg/cm2 (x0.0980665 -> MPa) | AI36: Formulation from text (polymer/Perhexa 25B/TAIC/filler = 100/1/2/15); props Table 5, F-radical Table 4. O3 water exposure weight loss 14.7%. No compression set reported. Cure: press 160C x 10 min + oven 180C x 4 h.
A37: US8173727B2 | B37: patent | C37: Daikin Industries, Ltd. | D37: Crosslinkable elastomer composition and molded article using the same | E37: https://patents.google.com/patent/US8173727B2/en | F37: Example 8 | G37: FFKM | H37: TFE/PMVE copolymer (67/33 mol%) | I37: peroxide | J37: 100 | K37: 0 | L37: 0 | M37: 0 | N37: 0 | O37: 0 | P37: 0 | Q37: 0 | R37: 0 | S37: 1 | T37: 2 | U37: 0 | V37: 0 | W37: 0 | X37: 0 | Y37: no filler; Perhexa 25B 2; TAIC 1 (as stated) | Z37: 65 | AA37: 13.73 | AB37: 210 | AC37: 2.94 | AF37: 0.4 | AG37: high-density F radical (NF3/Ar 1/1 SLM, 5 torr, ASTRON generator), 200C, 2 h | AH37: M100 and tensile in kg/cm2 (x0.0980665 -> MPa) | AI37: Text: polymer, Perhexa 25B and TAIC mixed at weight ratio 100/2/1 (note Example 1 used 100/1/2); recorded as stated. Props Table 5. No compression set reported.
A38: US8173727B2 | B38: patent | C38: Daikin Industries, Ltd. | D38: Crosslinkable elastomer composition and molded article using the same | E38: https://patents.google.com/patent/US8173727B2/en | F38: Example 9 | G38: FFKM | H38: TFE/perfluoroalkyl vinyl ether/cyano-group monomer 59.4/40.1/0.5 mol (Daikin) | I38: nitrile_other | J38: 100 | K38: 0 | L38: 0 | M38: 0 | N38: 0 | O38: 0 | P38: 0 | Q38: 15 | R38: 0 | S38: 0 | T38: 0 | U38: 1.2 | V38: 0 | W38: 0 | X38: 0 | Y38: AlN MAN-10 (200 nm) 15; crosslinker 6,6'-dianilino-3,3'-[2,2,2-trifluoro-1-(trifluoromethyl)ethylidene]dianiline 1.2 | AA38: 14.42 | AB38: 335 | AC38: 2.26 | AD38: 42 | AE38: 300C x 70h, AS-568A-214 O-ring (JIS K6262) | AF38: 0.11 | AG38: high-density F radical (NF3/Ar 1/1 SLM, 5 torr, ASTRON generator), 200C, 2 h | AH38: M100 and tensile in kgf/cm2 (x0.0980665 -> MPa); hardness reported as IRHD (not stored) | AI38: Formulation from text; props Table 7 (hardness IRHD 69, not Shore A). F-radical weight loss at 300C 1.08%; O3 weight loss 2.7%. Cure: press 180C x 10 min + oven 290C x 18 h.
A39: US8173727B2 | B39: patent | C39: Daikin Industries, Ltd. | D39: Crosslinkable elastomer composition and molded article using the same | E39: https://patents.google.com/patent/US8173727B2/en | F39: Example 10 | G39: FFKM | H39: TFE/perfluoroalkyl vinyl ether/cyano-group monomer 59.4/40.1/0.5 mol (Daikin) | I39: nitrile_other | J39: 100 | K39: 0 | L39: 0 | M39: 0 | N39: 0 | O39: 0 | P39: 0 | Q39: 15 | R39: 0 | S39: 0 | T39: 0 | U39: 1.2 | V39: 0 | W39: 0 | X39: 0 | Y39: Si3N4 SN-E10 (500 nm) 15; crosslinker 6,6'-dianilino-3,3'-[2,2,2-trifluoro-1-(trifluoromethyl)ethylidene]dianiline 1.2 | AA39: 12.85 | AB39: 25 | AC39: 2.94 | AD39: 27 | AE39: 300C x 70h, AS-568A-214 O-ring (JIS K6262) | AF39: 0.2 | AG39: high-density F radical (NF3/Ar 1/1 SLM, 5 torr, ASTRON generator), 200C, 2 h | AH39: M100 and tensile in kgf/cm2 (x0.0980665 -> MPa); hardness reported as IRHD (not stored) | AI39: Formulation from text; props Table 7 (hardness IRHD 70, not Shore A). F-radical weight loss at 300C 0.4%; O3 weight loss 2.6%. Cure: press 180C x 10 min + oven 290C x 18 h. Elongation 25% as printed (inconsistent with M100 value; possible typo in source).
A40: US8173727B2 | B40: patent | C40: Daikin Industries, Ltd. | D40: Crosslinkable elastomer composition and molded article using the same | E40: https://patents.google.com/patent/US8173727B2/en | F40: Example 11 | G40: FFKM | H40: TFE/perfluoroalkyl vinyl ether/cyano-group monomer 59.4/40.1/0.5 mol (Daikin) | I40: nitrile_other | J40: 100 | K40: 0 | L40: 0 | M40: 0 | N40: 0 | O40: 0 | P40: 0 | Q40: 15 | R40: 0 | S40: 0 | T40: 0 | U40: 1.2 | V40: 0 | W40: 0 | X40: 0 | Y40: SiC DU A-1 (450 nm) 15; crosslinker 6,6'-dianilino-3,3'-[2,2,2-trifluoro-1-(trifluoromethyl)ethylidene]dianiline 1.2 | AA40: 14.91 | AB40: 288 | AC40: 2.45 | AD40: 32 | AE40: 300C x 70h, AS-568A-214 O-ring (JIS K6262) | AF40: 0.2 | AG40: high-density F radical (NF3/Ar 1/1 SLM, 5 torr, ASTRON generator), 200C, 2 h | AH40: M100 and tensile in kgf/cm2 (x0.0980665 -> MPa); hardness reported as IRHD (not stored) | AI40: Formulation from text; props Table 7 (hardness IRHD 67, not Shore A). F-radical weight loss at 300C 0.42%; O3 weight loss 2.6%. Cure: press 180C x 10 min + oven 290C x 18 h.
A41: US8173727B2 | B41: patent | C41: Daikin Industries, Ltd. | D41: Crosslinkable elastomer composition and molded article using the same | E41: https://patents.google.com/patent/US8173727B2/en | F41: Example 12 | G41: FFKM | H41: TFE/perfluoroalkyl vinyl ether/cyano-group monomer 59.4/40.1/0.5 mol (Daikin) | I41: nitrile_other | J41: 100 | K41: 20 | L41: 0 | M41: 0 | N41: 0 | O41: 0 | P41: 0 | Q41: 0 | R41: 0 | S41: 0 | T41: 0 | U41: 0.8 | V41: 0 | W41: 0 | X41: 0 | Y41: carbon black Thermax N-990 20; crosslinker 6,6'-dianilino-3,3'-[2,2,2-trifluoro-1-(trifluoromethyl)ethylidene]dianiline 0.8 | AA41: 19.52 | AB41: 273 | AC41: 5 | AD41: 38 | AE41: 300C x 70h, AS-568A-214 O-ring (JIS K6262) | AF41: 0.15 | AG41: high-density F radical (NF3/Ar 1/1 SLM, 5 torr, ASTRON generator), 200C, 2 h | AH41: M100 and tensile in kgf/cm2 (x0.0980665 -> MPa); hardness reported as IRHD (not stored) | AI41: Formulation from text; props Table 7 (hardness IRHD 75, not Shore A). F-radical weight loss at 300C 0.17%; O3 weight loss 4.6%. Cure: press 180C x 10 min + oven 290C x 18 h.
A42: US8173727B2 | B42: patent | C42: Daikin Industries, Ltd. | D42: Crosslinkable elastomer composition and molded article using the same | E42: https://patents.google.com/patent/US8173727B2/en | F42: Example 13 | G42: FFKM | H42: TFE/perfluoroalkyl vinyl ether/cyano-group monomer 59.4/40.1/0.5 mol (Daikin) | I42: nitrile_other | J42: 100 | K42: 0 | L42: 15 | M42: 0 | N42: 0 | O42: 0 | P42: 0 | Q42: 0 | R42: 0 | S42: 0 | T42: 0 | U42: 1.2 | V42: 0 | W42: 0 | X42: 0 | Y42: SiO2 M-7D (15 nm) 15; crosslinker 6,6'-dianilino-3,3'-[2,2,2-trifluoro-1-(trifluoromethyl)ethylidene]dianiline 1.2 | AA42: 13.34 | AB42: 275 | AC42: 4.9 | AE42: 300C x 70h, AS-568A-214 O-ring (JIS K6262) | AF42: 0.23 | AG42: high-density F radical (NF3/Ar 1/1 SLM, 5 torr, ASTRON generator), 200C, 2 h | AH42: M100 and tensile in kgf/cm2 (x0.0980665 -> MPa); hardness reported as IRHD (not stored) | AI42: Formulation from text; props Table 7 (hardness IRHD 74, not Shore A). F-radical weight loss at 300C 0.51%; O3 weight loss 2.9%. Cure: press 180C x 10 min + oven 290C x 18 h.
A43: US8173727B2 | B43: patent | C43: Daikin Industries, Ltd. | D43: Crosslinkable elastomer composition and molded article using the same | E43: https://patents.google.com/patent/US8173727B2/en | F43: Example 14 | G43: FFKM | H43: TFE/perfluoroalkyl vinyl ether/cyano-group monomer 59.4/40.1/0.5 mol (Daikin) | I43: nitrile_other | J43: 100 | K43: 0 | L43: 0 | M43: 15 | N43: 0 | O43: 0 | P43: 0 | Q43: 0 | R43: 0 | S43: 0 | T43: 0 | U43: 1.2 | V43: 0 | W43: 0 | X43: 0 | Y43: alpha-Al2O3 AKP-53 (200 nm) 15; crosslinker 6,6'-dianilino-3,3'-[2,2,2-trifluoro-1-(trifluoromethyl)ethylidene]dianiline 1.2 | AA43: 15.79 | AB43: 307 | AC43: 2.26 | AD43: 45 | AE43: 300C x 70h, AS-568A-214 O-ring (JIS K6262) | AF43: 3.21 | AG43: high-density F radical (NF3/Ar 1/1 SLM, 5 torr, ASTRON generator), 200C, 2 h | AH43: M100 and tensile in kgf/cm2 (x0.0980665 -> MPa); hardness reported as IRHD (not stored) | AI43: Formulation from text; props Table 7 (hardness IRHD 66, not Shore A). F-radical weight loss at 300C 5.66%; O3 weight loss 2.6%. Cure: press 180C x 10 min + oven 290C x 18 h.
A44: US8211964B2 | B44: patent | C44: Daikin Industries, Ltd. | D44: Curable composition, molded article obtained from same and process for production of molded article | E44: https://patents.google.com/patent/US8211964B2/en | F44: Example 2 | G44: FFKM | H44: TFE/PMVE/CNVE (CF2=CFOCF2CF(CF3)OCF2CF2CN) elastomer with cyano end groups (Preparation Example 1) | I44: nitrile_triazine | J44: 100 | K44: 0 | L44: 0 | M44: 0 | N44: 0 | O44: 0 | P44: 0 | Q44: 0 | R44: 0 | S44: 0 | T44: 0 | U44: 0.35 | V44: 0 | W44: 0 | X44: 0 | Y44: Si3N4 SN-A00 (30 nm) 0.35 as sole curing catalyst | Z44: 57.2 | AA44: 9.32 | AB44: 295 | AC44: 1.18 | AD44: 18 | AE44: 200C x 72h, AS-568A-214 O-ring | AH44: M100 and Tb in kgf/cm2 (x0.0980665 -> MPa) | AI44: Table 1; AFTA-Ph = 2,2-bis[3-amino-4-(N-phenylamino)phenyl]hexafluoropropane; nitrile_curative = sum of curatives. CS 250C x 72h 18%; 300C x 72h 33%. Cure: press 180C for T90 + oven 290C x 18 h. CS per JIS K6301 on AS-568A-214 O-ring. Example 1 (Si3N4 0.20) omitted: no properties reported.
A45: US8211964B2 | B45: patent | C45: Daikin Industries, Ltd. | D45: Curable composition, molded article obtained from same and process for production of molded article | E45: https://patents.google.com/patent/US8211964B2/en | F45: Example 3 | G45: FFKM | H45: TFE/PMVE/CNVE (CF2=CFOCF2CF(CF3)OCF2CF2CN) elastomer with cyano end groups (Preparation Example 1) | I45: nitrile_triazine | J45: 100 | K45: 0 | L45: 0 | M45: 0 | N45: 0 | O45: 0 | P45: 0 | Q45: 0 | R45: 0 | S45: 0 | T45: 0 | U45: 0.4 | V45: 0 | W45: 0 | X45: 0 | Y45: Si3N4 SN-A00 (30 nm) 0.40 as sole curing catalyst | Z45: 58 | AA45: 10 | AB45: 265 | AC45: 1.37 | AD45: 17 | AE45: 200C x 72h, AS-568A-214 O-ring | AH45: M100 and Tb in kgf/cm2 (x0.0980665 -> MPa) | AI45: Table 1; AFTA-Ph = 2,2-bis[3-amino-4-(N-phenylamino)phenyl]hexafluoropropane; nitrile_curative = sum of curatives. CS 250C x 72h 17%; 300C x 72h 30%. Cure: press 180C for T90 + oven 290C x 18 h. CS per JIS K6301 on AS-568A-214 O-ring. Example 1 (Si3N4 0.20) omitted: no properties reported.
A46: US8211964B2 | B46: patent | C46: Daikin Industries, Ltd. | D46: Curable composition, molded article obtained from same and process for production of molded article | E46: https://patents.google.com/patent/US8211964B2/en | F46: Example 4 | G46: FFKM | H46: TFE/PMVE/CNVE (CF2=CFOCF2CF(CF3)OCF2CF2CN) elastomer with cyano end groups (Preparation Example 1) | I46: nitrile_triazine | J46: 100 | K46: 0 | L46: 0 | M46: 0 | N46: 0 | O46: 0 | P46: 0 | Q46: 20 | R46: 0 | S46: 0 | T46: 0 | U46: 0 | V46: 0 | W46: 0 | X46: 0 | Y46: Si3N4 SN-E10 pulverized (<=300 nm) 20; acts as both filler and sole curing catalyst (no separate curative) | Z46: 76 | AA46: 12.75 | AB46: 180 | AC46: 5 | AD46: 42 | AE46: 250C x 72h, AS-568A-214 O-ring | AH46: M100 and Tb in kgf/cm2 (x0.0980665 -> MPa) | AI46: Table 1; AFTA-Ph = 2,2-bis[3-amino-4-(N-phenylamino)phenyl]hexafluoropropane; nitrile_curative = sum of curatives. Only 250C CS reported. Cure: press 180C for T90 + oven 290C x 18 h. CS per JIS K6301 on AS-568A-214 O-ring. Example 1 (Si3N4 0.20) omitted: no properties reported.
A47: US8211964B2 | B47: patent | C47: Daikin Industries, Ltd. | D47: Curable composition, molded article obtained from same and process for production of molded article | E47: https://patents.google.com/patent/US8211964B2/en | F47: Example 5 | G47: FFKM | H47: TFE/PMVE/CNVE (CF2=CFOCF2CF(CF3)OCF2CF2CN) elastomer with cyano end groups (Preparation Example 1) | I47: nitrile_triazine | J47: 100 | K47: 0 | L47: 0 | M47: 0 | N47: 0 | O47: 0 | P47: 0 | Q47: 20 | R47: 0 | S47: 0 | T47: 0 | U47: 0 | V47: 0 | W47: 0 | X47: 0 | Y47: AlN pulverized (Tokuyama H grade) 20; acts as both filler and sole curing catalyst (no separate curative) | Z47: 78 | AA47: 11.77 | AB47: 170 | AC47: 4.9 | AD47: 48 | AE47: 250C x 72h, AS-568A-214 O-ring | AH47: M100 and Tb in kgf/cm2 (x0.0980665 -> MPa) | AI47: Table 1; AFTA-Ph = 2,2-bis[3-amino-4-(N-phenylamino)phenyl]hexafluoropropane; nitrile_curative = sum of curatives. Only 250C CS reported. Cure: press 180C for T90 + oven 290C x 18 h. CS per JIS K6301 on AS-568A-214 O-ring. Example 1 (Si3N4 0.20) omitted: no properties reported.
A48: US8211964B2 | B48: patent | C48: Daikin Industries, Ltd. | D48: Curable composition, molded article obtained from same and process for production of molded article | E48: https://patents.google.com/patent/US8211964B2/en | F48: Example 6 | G48: FFKM | H48: TFE/PMVE/CNVE (CF2=CFOCF2CF(CF3)OCF2CF2CN) elastomer with cyano end groups (Preparation Example 1) | I48: nitrile_other | J48: 100 | K48: 0 | L48: 0 | M48: 0 | N48: 0 | O48: 0 | P48: 0 | Q48: 0 | R48: 15 | S48: 0 | T48: 0 | U48: 1.3 | V48: 0 | W48: 0 | X48: 0 | Y48: AFTA-Ph 1.2 + Si3N4 SN-A00 (30 nm) 0.1; polyimide UIP-S 15 | Z48: 73 | AA48: 13.04 | AB48: 234 | AC48: 5.2 | AD48: 24 | AE48: 300C x 72h, AS-568A-214 O-ring | AH48: M100 and Tb in kgf/cm2 (x0.0980665 -> MPa) | AI48: Table 2; AFTA-Ph = 2,2-bis[3-amino-4-(N-phenylamino)phenyl]hexafluoropropane; nitrile_curative = sum of curatives. CS 275C x 72h 10%, 275C x 168h 14%, 300C x 168h 35%. Cure: press 180C for T90 + oven 290C x 18 h. CS per JIS K6301 on AS-568A-214 O-ring. Example 1 (Si3N4 0.20) omitted: no properties reported.
A49: US8211964B2 | B49: patent | C49: Daikin Industries, Ltd. | D49: Curable composition, molded article obtained from same and process for production of molded article | E49: https://patents.google.com/patent/US8211964B2/en | F49: Comparative Example 1 | G49: FFKM | H49: TFE/PMVE/CNVE (CF2=CFOCF2CF(CF3)OCF2CF2CN) elastomer with cyano end groups (Preparation Example 1) | I49: nitrile_other | J49: 100 | K49: 0 | L49: 0 | M49: 0 | N49: 0 | O49: 0 | P49: 0 | Q49: 0 | R49: 15 | S49: 0 | T49: 0 | U49: 1.2 | V49: 0 | W49: 0 | X49: 0 | Y49: AFTA-Ph 1.2; polyimide UIP-S 15 | Z49: 73 | AA49: 12.85 | AB49: 256 | AC49: 4.9 | AD49: 31 | AE49: 300C x 72h, AS-568A-214 O-ring | AH49: M100 and Tb in kgf/cm2 (x0.0980665 -> MPa) | AI49: Table 2; AFTA-Ph = 2,2-bis[3-amino-4-(N-phenylamino)phenyl]hexafluoropropane; nitrile_curative = sum of curatives. CS 275C x 72h 18%, 275C x 168h 26%, 300C x 168h 44%. Cure: press 180C for T90 + oven 290C x 18 h. CS per JIS K6301 on AS-568A-214 O-ring. Example 1 (Si3N4 0.20) omitted: no properties reported.
A50: US8211964B2 | B50: patent | C50: Daikin Industries, Ltd. | D50: Curable composition, molded article obtained from same and process for production of molded article | E50: https://patents.google.com/patent/US8211964B2/en | F50: Example 7 | G50: FFKM | H50: TFE/PMVE/CNVE (CF2=CFOCF2CF(CF3)OCF2CF2CN) elastomer with cyano end groups (Preparation Example 1) | I50: nitrile_other | J50: 100 | K50: 0 | L50: 10 | M50: 0 | N50: 0 | O50: 0 | P50: 0 | Q50: 0 | R50: 0 | S50: 0 | T50: 0 | U50: 1.3 | V50: 0 | W50: 0 | X50: 0 | Y50: AFTA-Ph 1.2 + Si3N4 SN-A00 (30 nm) 0.1; SiO2 M-7D 10 | Z50: 77 | AA50: 17.65 | AB50: 310 | AC50: 5 | AD50: 53 | AE50: 300C x 72h, AS-568A-214 O-ring | AH50: M100 and Tb in kgf/cm2 (x0.0980665 -> MPa) | AI50: Table 2; AFTA-Ph = 2,2-bis[3-amino-4-(N-phenylamino)phenyl]hexafluoropropane; nitrile_curative = sum of curatives. CS 275C x 72h 43%, 275C x 168h 50%, 300C x 168h 71%. Cure: press 180C for T90 + oven 290C x 18 h. CS per JIS K6301 on AS-568A-214 O-ring. Example 1 (Si3N4 0.20) omitted: no properties reported.
A51: US8211964B2 | B51: patent | C51: Daikin Industries, Ltd. | D51: Curable composition, molded article obtained from same and process for production of molded article | E51: https://patents.google.com/patent/US8211964B2/en | F51: Comparative Example 2 | G51: FFKM | H51: TFE/PMVE/CNVE (CF2=CFOCF2CF(CF3)OCF2CF2CN) elastomer with cyano end groups (Preparation Example 1) | I51: nitrile_other | J51: 100 | K51: 0 | L51: 10 | M51: 0 | N51: 0 | O51: 0 | P51: 0 | Q51: 0 | R51: 0 | S51: 0 | T51: 0 | U51: 1.2 | V51: 0 | W51: 0 | X51: 0 | Y51: AFTA-Ph 1.2; SiO2 M-7D 10 | Z51: 75 | AA51: 17.06 | AB51: 288 | AC51: 5.1 | AD51: 72 | AE51: 300C x 72h, AS-568A-214 O-ring | AH51: M100 and Tb in kgf/cm2 (x0.0980665 -> MPa) | AI51: Table 2; AFTA-Ph = 2,2-bis[3-amino-4-(N-phenylamino)phenyl]hexafluoropropane; nitrile_curative = sum of curatives. CS 275C x 72h 58%, 275C x 168h 67%, 300C x 168h 88%. Cure: press 180C for T90 + oven 290C x 18 h. CS per JIS K6301 on AS-568A-214 O-ring. Example 1 (Si3N4 0.20) omitted: no properties reported.
A52: US8211964B2 | B52: patent | C52: Daikin Industries, Ltd. | D52: Curable composition, molded article obtained from same and process for production of molded article | E52: https://patents.google.com/patent/US8211964B2/en | F52: Example 8 | G52: FFKM | H52: TFE/PMVE/CNVE (CF2=CFOCF2CF(CF3)OCF2CF2CN) elastomer with cyano end groups (Preparation Example 1) | I52: nitrile_other | J52: 100 | K52: 20 | L52: 0 | M52: 0 | N52: 0 | O52: 0 | P52: 0 | Q52: 5 | R52: 0 | S52: 0 | T52: 0 | U52: 1 | V52: 0 | W52: 0 | X52: 0 | Y52: AFTA-Ph 1.0; Si3N4 SN-E10 (<=300 nm) 5 (curing accelerator, counted as inorganic filler); carbon Thermax N990 20 | Z52: 83 | AA52: 18.63 | AB52: 205 | AC52: 6.37 | AD52: 32 | AE52: 300C x 72h, AS-568A-214 O-ring | AH52: M100 and Tb in kgf/cm2 (x0.0980665 -> MPa) | AI52: Table 2; AFTA-Ph = 2,2-bis[3-amino-4-(N-phenylamino)phenyl]hexafluoropropane; nitrile_curative = sum of curatives. CS 275C x 72h 22%, 275C x 168h 25%, 300C x 168h 39%. Cure: press 180C for T90 + oven 290C x 18 h. CS per JIS K6301 on AS-568A-214 O-ring. Example 1 (Si3N4 0.20) omitted: no properties reported.
A53: US8211964B2 | B53: patent | C53: Daikin Industries, Ltd. | D53: Curable composition, molded article obtained from same and process for production of molded article | E53: https://patents.google.com/patent/US8211964B2/en | F53: Comparative Example 3 | G53: FFKM | H53: TFE/PMVE/CNVE (CF2=CFOCF2CF(CF3)OCF2CF2CN) elastomer with cyano end groups (Preparation Example 1) | I53: nitrile_other | J53: 100 | K53: 20 | L53: 0 | M53: 0 | N53: 0 | O53: 0 | P53: 0 | Q53: 0 | R53: 0 | S53: 0 | T53: 0 | U53: 1 | V53: 0 | W53: 0 | X53: 0 | Y53: AFTA-Ph 1.0; carbon Thermax N990 20 | Z53: 73 | AA53: 22.56 | AB53: 200 | AC53: 5.88 | AD53: 30 | AE53: 300C x 72h, AS-568A-214 O-ring | AH53: M100 and Tb in kgf/cm2 (x0.0980665 -> MPa) | AI53: Table 2; AFTA-Ph = 2,2-bis[3-amino-4-(N-phenylamino)phenyl]hexafluoropropane; nitrile_curative = sum of curatives. CS 275C x 72h 22%, 275C x 168h 25%, 300C x 168h 38%. Cure: press 180C for T90 + oven 290C x 18 h. CS per JIS K6301 on AS-568A-214 O-ring. Example 1 (Si3N4 0.20) omitted: no properties reported.
A54: US11753523B2 | B54: patent | C54: Daikin Industries, Ltd. | D54: Crosslinkable elastomer composition and fluororubber molded article | E54: https://patents.google.com/patent/US11753523B2/en | F54: Example 1 | G54: FFKM | H54: TFE/PMVE/CNVE 59.4/40.1/0.5 mol | I54: nitrile_other | J54: 100 | K54: 0 | L54: 0 | M54: 0 | N54: 0 | O54: 0 | P54: 0 | Q54: 10 | R54: 0 | S54: 0 | T54: 0 | U54: 0.9 | V54: 0 | W54: 0 | X54: 0 | Y54: surface-oxidized SiC (NM-SiC 30 nm heat-treated 800C x 1 h in air) 10; NphAF 0.9 (2,2-bis[3-amino-4-(N-phenylamino)phenyl]hexafluoropropane) | Z54: 72 | AD54: 33 | AE54: 300C x 70h, AS-568A-214 O-ring (JIS K6262) | AF54: 1.9 | AG54: O2 plasma, ICP RIE-101iPH, 16 sccm, 400 W, 2.66 Pa, 30 min, 100C, P-24 O-ring | AH54: as reported (Shore A, %) | AI54: Table 1 (US11753523B2). CS 300C x 168h: n/r%. NF3 plasma weight loss: 1.79%. Cure: press 180C x 30 min + oven (200-)290C x 18 h.
A55: US11753523B2 | B55: patent | C55: Daikin Industries, Ltd. | D55: Crosslinkable elastomer composition and fluororubber molded article | E55: https://patents.google.com/patent/US11753523B2/en | F55: Example 2 | G55: FFKM | H55: TFE/PMVE/CNVE 59.4/40.1/0.5 mol | I55: nitrile_triazine | J55: 100 | K55: 0 | L55: 0 | M55: 0 | N55: 0 | O55: 0 | P55: 0 | Q55: 10 | R55: 0 | S55: 0 | T55: 0 | U55: 0.4 | V55: 0 | W55: 0 | X55: 0 | Y55: surface-oxidized SiC (NM-SiC 30 nm heat-treated 800C x 1 h in air) 10; Si3N4 (0.03 um) 0.4 (triazine-cure catalyst) | Z55: 71 | AD55: 33 | AE55: 300C x 70h, AS-568A-214 O-ring (JIS K6262) | AF55: 1.89 | AG55: O2 plasma, ICP RIE-101iPH, 16 sccm, 400 W, 2.66 Pa, 30 min, 100C, P-24 O-ring | AH55: as reported (Shore A, %) | AI55: Table 1 (US11753523B2). CS 300C x 168h: n/r%. NF3 plasma weight loss: 1.78%. Cure: press 180C x 30 min + oven (200-)290C x 18 h.
...

Sheet Model_Data
A1: row_id | B1: source_id | C1: assignee | D1: example_label | E1: polymer_type | F1: polymer_grade | G1: cure_system | H1: polymer_phr | I1: carbon_black_phr | J1: silica_phr | K1: alumina_phr | L1: barium_sulfate_phr | M1: titanium_oxide_phr | N1: fluororesin_phr | O1: other_inorganic_filler_phr | P1: organic_additive_phr | Q1: coagent_phr | R1: peroxide_phr | S1: nitrile_curative_phr | T1: other_curative_phr | U1: acid_acceptor_phr | V1: processing_aid_phr | W1: hardness_shoreA | X1: tensile_MPa | Y1: elongation_pct | Z1: m100_MPa | AA1: compression_set_pct | AB1: cs_condition | AC1: cs_temp_C | AD1: total_filler_phr | AE1: used_hardness_shoreA | AF1: used_tensile_MPa | AG1: used_elongation_pct | AH1: used_m100_MPa | AI1: used_compression_set_pct
A2: G001 | B2: US7678858B2 | C2: Daikin Industries, Ltd. | D2: Example 1 | E2: FFKM | F2: DAI-EL PERFLO GA-105 (TFE/perfluoro(alkyl vinyl ether), iodine cure site) | G2: peroxide | H2: 100 | I2: 0 | J2: 0 | K2: 15 | L2: 0 | M2: 0 | N2: 0 | O2: 0 | P2: 2 | Q2: 2 | R2: 1 | S2: 0 | T2: 0 | U2: 0 | V2: 0 | W2: 78 | X2: 24.52 | Y2: 170 | Z2: 9.02 | AA2: 21 | AB2: 200C x 70h, 25% compression, P-24 O-ring (JIS K6301) | AC2: 200 | AD2: =I2+J2+K2+L2+M2+N2+O2+P2 | AE2: 1 | AF2: 1 | AG2: 1 | AH2: 1 | AI2: 1
A3: G002 | B3: US7678858B2 | C3: Daikin Industries, Ltd. | D3: Example 2 | E3: FFKM | F3: DAI-EL PERFLO GA-105 (TFE/perfluoro(alkyl vinyl ether), iodine cure site) | G3: peroxide | H3: 100 | I3: 0 | J3: 0 | K3: 15 | L3: 0 | M3: 0 | N3: 0 | O3: 0 | P3: 2 | Q3: 2 | R3: 1 | S3: 0 | T3: 0 | U3: 0 | V3: 0 | W3: 79 | X3: 26.18 | Y3: 170 | Z3: 9.32 | AA3: 22 | AB3: 200C x 70h, 25% compression, P-24 O-ring (JIS K6301) | AC3: 200 | AD3: =I3+J3+K3+L3+M3+N3+O3+P3 | AE3: 1 | AF3: 1 | AG3: 1 | AH3: 1 | AI3: 1
A4: G003 | B4: US7678858B2 | C4: Daikin Industries, Ltd. | D4: Example 3 | E4: FFKM | F4: DAI-EL PERFLO GA-105 (TFE/perfluoro(alkyl vinyl ether), iodine cure site) | G4: peroxide | H4: 100 | I4: 0 | J4: 0 | K4: 15 | L4: 0 | M4: 0 | N4: 0 | O4: 0 | P4: 2 | Q4: 2 | R4: 1 | S4: 0 | T4: 0 | U4: 0 | V4: 0 | W4: 78 | X4: 24.91 | Y4: 170 | Z4: 9.12 | AA4: 21 | AB4: 200C x 70h, 25% compression, P-24 O-ring (JIS K6301) | AC4: 200 | AD4: =I4+J4+K4+L4+M4+N4+O4+P4 | AE4: 1 | AF4: 1 | AG4: 1 | AH4: 1 | AI4: 1
A5: G004 | B5: US7678858B2 | C5: Daikin Industries, Ltd. | D5: Example 4 | E5: FFKM | F5: DAI-EL PERFLO GA-105 (TFE/perfluoro(alkyl vinyl ether), iodine cure site) | G5: peroxide | H5: 100 | I5: 0 | J5: 0 | K5: 15 | L5: 0 | M5: 0 | N5: 0 | O5: 0 | P5: 2 | Q5: 2 | R5: 1 | S5: 0 | T5: 0 | U5: 0 | V5: 0 | W5: 79 | X5: 23.54 | Y5: 170 | Z5: 9.32 | AA5: 21 | AB5: 200C x 70h, 25% compression, P-24 O-ring (JIS K6301) | AC5: 200 | AD5: =I5+J5+K5+L5+M5+N5+O5+P5 | AE5: 1 | AF5: 1 | AG5: 1 | AH5: 1 | AI5: 1
A6: G005 | B6: US7678858B2 | C6: Daikin Industries, Ltd. | D6: Example 5 | E6: FFKM | F6: DAI-EL PERFLO GA-105 (TFE/perfluoro(alkyl vinyl ether), iodine cure site) | G6: peroxide | H6: 100 | I6: 0 | J6: 0 | K6: 15 | L6: 0 | M6: 0 | N6: 0 | O6: 0 | P6: 2 | Q6: 2 | R6: 1 | S6: 0 | T6: 0 | U6: 0 | V6: 0 | W6: 78 | X6: 23.24 | Y6: 170 | Z6: 9.12 | AA6: 23 | AB6: 200C x 70h, 25% compression, P-24 O-ring (JIS K6301) | AC6: 200 | AD6: =I6+J6+K6+L6+M6+N6+O6+P6 | AE6: 1 | AF6: 1 | AG6: 1 | AH6: 1 | AI6: 1
A7: G006 | B7: US7678858B2 | C7: Daikin Industries, Ltd. | D7: Example 6 | E7: FFKM | F7: DAI-EL PERFLO GA-105 (TFE/perfluoro(alkyl vinyl ether), iodine cure site) | G7: peroxide | H7: 100 | I7: 0 | J7: 0 | K7: 15 | L7: 0 | M7: 0 | N7: 0 | O7: 0 | P7: 2 | Q7: 2 | R7: 1 | S7: 0 | T7: 0 | U7: 0 | V7: 0 | W7: 78 | X7: 23.63 | Y7: 170 | Z7: 8.34 | AA7: 28 | AB7: 200C x 70h, 25% compression, P-24 O-ring (JIS K6301) | AC7: 200 | AD7: =I7+J7+K7+L7+M7+N7+O7+P7 | AE7: 1 | AF7: 1 | AG7: 1 | AH7: 1 | AI7: 1
A8: G007 | B8: US7678858B2 | C8: Daikin Industries, Ltd. | D8: Example 7 | E8: FFKM | F8: DAI-EL PERFLO GA-105 (TFE/perfluoro(alkyl vinyl ether), iodine cure site) | G8: peroxide | H8: 100 | I8: 0 | J8: 0 | K8: 15 | L8: 0 | M8: 0 | N8: 0 | O8: 0 | P8: 2 | Q8: 2 | R8: 1 | S8: 0 | T8: 0 | U8: 0 | V8: 0 | W8: 79 | X8: 25.11 | Y8: 200 | Z8: 5.98 | AA8: 48 | AB8: 200C x 70h, 25% compression, P-24 O-ring (JIS K6301) | AC8: 200 | AD8: =I8+J8+K8+L8+M8+N8+O8+P8 | AE8: 1 | AF8: 1 | AG8: 1 | AH8: 1 | AI8: 1
A9: G008 | B9: US7678858B2 | C9: Daikin Industries, Ltd. | D9: Example 8 | E9: FFKM | F9: DAI-EL PERFLO GA-105 (TFE/perfluoro(alkyl vinyl ether), iodine cure site) | G9: peroxide | H9: 100 | I9: 0 | J9: 0 | K9: 15 | L9: 0 | M9: 0 | N9: 0 | O9: 0 | P9: 2 | Q9: 2 | R9: 1 | S9: 0 | T9: 0 | U9: 0 | V9: 0 | W9: 78 | X9: 24.71 | Y9: 190 | Z9: 6.96 | AA9: 45 | AB9: 200C x 70h, 25% compression, P-24 O-ring (JIS K6301) | AC9: 200 | AD9: =I9+J9+K9+L9+M9+N9+O9+P9 | AE9: 1 | AF9: 1 | AG9: 1 | AH9: 1 | AI9: 1
A10: G009 | B10: US7678858B2 | C10: Daikin Industries, Ltd. | D10: Example 9 | E10: FFKM | F10: DAI-EL PERFLO GA-105 (TFE/perfluoro(alkyl vinyl ether), iodine cure site) | G10: peroxide | H10: 100 | I10: 0 | J10: 0 | K10: 15 | L10: 0 | M10: 0 | N10: 0 | O10: 0 | P10: 2 | Q10: 2 | R10: 1 | S10: 0 | T10: 0 | U10: 0 | V10: 0 | W10: 80 | X10: 23.14 | Y10: 170 | Z10: 8.92 | AA10: 28 | AB10: 200C x 70h, 25% compression, P-24 O-ring (JIS K6301) | AC10: 200 | AD10: =I10+J10+K10+L10+M10+N10+O10+P10 | AE10: 1 | AF10: 1 | AG10: 1 | AH10: 1 | AI10: 1
A11: G010 | B11: US7678858B2 | C11: Daikin Industries, Ltd. | D11: Comparative Example 1 | E11: FFKM | F11: DAI-EL PERFLO GA-105 (TFE/perfluoro(alkyl vinyl ether), iodine cure site) | G11: peroxide | H11: 100 | I11: 0 | J11: 0 | K11: 15 | L11: 0 | M11: 0 | N11: 0 | O11: 0 | P11: 0 | Q11: 2 | R11: 1 | S11: 0 | T11: 0 | U11: 0 | V11: 0 | W11: 75 | X11: 23.83 | Y11: 160 | Z11: 8.83 | AA11: 21 | AB11: 200C x 70h, 25% compression, P-24 O-ring (JIS K6301) | AC11: 200 | AD11: =I11+J11+K11+L11+M11+N11+O11+P11 | AE11: 1 | AF11: 1 | AG11: 1 | AH11: 1 | AI11: 1
A12: G011 | B12: US7678858B2 | C12: Daikin Industries, Ltd. | D12: Example 10 | E12: FFKM | F12: DAI-EL PERFLO GA-105 (TFE/perfluoro(alkyl vinyl ether), iodine cure site) | G12: peroxide | H12: 100 | I12: 0 | J12: 0 | K12: 0 | L12: 0 | M12: 0 | N12: 0 | O12: 0 | P12: 15 | Q12: 2 | R12: 1 | S12: 0 | T12: 0 | U12: 0 | V12: 0 | W12: 82 | X12: 16.18 | Y12: 190 | Z12: 7.16 | AA12: 17 | AB12: 200C x 70h, 25% compression, P-24 O-ring (JIS K6301) | AC12: 200 | AD12: =I12+J12+K12+L12+M12+N12+O12+P12 | AE12: 1 | AF12: 1 | AG12: 1 | AH12: 1 | AI12: 1
A13: G012 | B13: US7678858B2 | C13: Daikin Industries, Ltd. | D13: Example 11 | E13: FFKM | F13: DAI-EL PERFLO GA-105 (TFE/perfluoro(alkyl vinyl ether), iodine cure site) | G13: peroxide | H13: 100 | I13: 0 | J13: 0 | K13: 15 | L13: 0 | M13: 0 | N13: 0 | O13: 0 | P13: 15 | Q13: 2 | R13: 1 | S13: 0 | T13: 0 | U13: 0 | V13: 0 | W13: 89 | X13: 19.71 | Y13: 140 | Z13: 13.73 | AA13: 33 | AB13: 200C x 70h, 25% compression, P-24 O-ring (JIS K6301) | AC13: 200 | AD13: =I13+J13+K13+L13+M13+N13+O13+P13 | AE13: 1 | AF13: 1 | AG13: 1 | AH13: 1 | AI13: 1
... A29: G028 | B29: US6803402B2 | C29: Daikin Industries, Ltd. | D29: Comparative Example 3 | E29: FFKM | F29: TFE/perfluoro(methyl vinyl ether) copolymer elastomer | G29: peroxide | H29: 100 | I29: 0 | J29: 0 | K29: 0 | L29: 0 | M29: 10 | N29: 0 | O29: 0 | P29: 0 | Q29: 3 | R29: 1 | S29: 0 | T29: 0 | U29: 0 | V29: 0 | W29: 59 | X29: 19.71 | Y29: 153 | Z29: 5.88 | AA29: 20 | AB29: 200C x 70h, 25% compression, AS-568A-214 O-ring (JIS K6301) | AC29: 200 | AD29: =I29+J29+K29+L29+M29+N29+O29+P29 | AE29: 1 | AF29: 1 | AG29: 1 | AH29: 1 | AI29: 1
A30: G029 | B30: US8173727B2 | C30: Daikin Industries, Ltd. | D30: Example 1 | E30: FFKM | F30: TFE/PMVE copolymer (67/33 mol%) | G30: peroxide | H30: 100 | I30: 0 | J30: 0 | K30: 0 | L30: 0 | M30: 0 | N30: 0 | O30: 0 | P30: 15 | Q30: 2 | R30: 1 | S30: 0 | T30: 0 | U30: 0 | V30: 0 | W30: 80 | X30: 15.69 | Y30: 170 | Z30: 9.81 | AD30: =I30+J30+K30+L30+M30+N30+O30+P30 | AE30: 1 | AF30: 1 | AG30: 1 | AH30: 1 | AI30: 0
A31: G030 | B31: US8173727B2 | C31: Daikin Industries, Ltd. | D31: Example 2 | E31: FFKM | F31: TFE/PMVE copolymer (67/33 mol%) | G31: peroxide | H31: 100 | I31: 0 | J31: 0 | K31: 0 | L31: 0 | M31: 0 | N31: 0 | O31: 0 | P31: 15 | Q31: 2 | R31: 1 | S31: 0 | T31: 0 | U31: 0 | V31: 0 | W31: 80 | X31: 16.67 | Y31: 160 | Z31: 12.75 | AD31: =I31+J31+K31+L31+M31+N31+O31+P31 | AE31: 1 | AF31: 1 | AG31: 1 | AH31: 1 | AI31: 0
A32: G031 | B32: US8173727B2 | C32: Daikin Industries, Ltd. | D32: Example 3 | E32: FFKM | F32: TFE/PMVE copolymer (67/33 mol%) | G32: peroxide | H32: 100 | I32: 0 | J32: 0 | K32: 0 | L32: 0 | M32: 0 | N32: 0 | O32: 0 | P32: 15 | Q32: 2 | R32: 1 | S32: 0 | T32: 0 | U32: 0 | V32: 0 | W32: 81 | X32: 18.14 | Y32: 140 | Z32: 15.2 | AD32: =I32+J32+K32+L32+M32+N32+O32+P32 | AE32: 1 | AF32: 1 | AG32: 1 | AH32: 1 | AI32: 0
A33: G032 | B33: US8173727B2 | C33: Daikin Industries, Ltd. | D33: Example 4 | E33: FFKM | F33: TFE/PMVE copolymer (67/33 mol%) | G33: peroxide | H33: 100 | I33: 0 | J33: 0 | K33: 0 | L33: 0 | M33: 0 | N33: 0 | O33: 0 | P33: 15 | Q33: 2 | R33: 1 | S33: 0 | T33: 0 | U33: 0 | V33: 0 | W33: 81 | X33: 19.12 | Y33: 120 | Z33: 16.18 | AD33: =I33+J33+K33+L33+M33+N33+O33+P33 | AE33: 1 | AF33: 1 | AG33: 1 | AH33: 1 | AI33: 0
A34: G033 | B34: US8173727B2 | C34: Daikin Industries, Ltd. | D34: Example 5 | E34: FFKM | F34: TFE/PMVE copolymer (67/33 mol%) | G34: peroxide | H34: 100 | I34: 0 | J34: 0 | K34: 0 | L34: 0 | M34: 0 | N34: 0 | O34: 0 | P34: 15 | Q34: 2 | R34: 1 | S34: 0 | T34: 0 | U34: 0 | V34: 0 | W34: 79 | X34: 10.79 | Y34: 190 | Z34: 5.88 | AD34: =I34+J34+K34+L34+M34+N34+O34+P34 | AE34: 1 | AF34: 1 | AG34: 1 | AH34: 1 | AI34: 0
A35: G034 | B35: US8173727B2 | C35: Daikin Industries, Ltd. | D35: Example 6 | E35: FFKM | F35: TFE/PMVE copolymer (67/33 mol%) | G35: peroxide | H35: 100 | I35: 0 | J35: 0 | K35: 15 | L35: 0 | M35: 0 | N35: 0 | O35: 0 | P35: 0 | Q35: 2 | R35: 1 | S35: 0 | T35: 0 | U35: 0 | V35: 0 | W35: 75 | X35: 23.54 | Y35: 160 | Z35: 9.81 | AD35: =I35+J35+K35+L35+M35+N35+O35+P35 | AE35: 1 | AF35: 1 | AG35: 1 | AH35: 1 | AI35: 0
A36: G035 | B36: US8173727B2 | C36: Daikin Industries, Ltd. | D36: Example 7 | E36: FFKM | F36: TFE/PMVE copolymer (67/33 mol%) | G36: peroxide | H36: 100 | I36: 15 | J36: 0 | K36: 0 | L36: 0 | M36: 0 | N36: 0 | O36: 0 | P36: 0 | Q36: 2 | R36: 1 | S36: 0 | T36: 0 | U36: 0 | V36: 0 | W36: 80 | X36: 19.61 | Y36: 180 | Z36: 9.81 | AD36: =I36+J36+K36+L36+M36+N36+O36+P36 | AE36: 1 | AF36: 1 | AG36: 1 | AH36: 1 | AI36: 0
A37: G036 | B37: US8173727B2 | C37: Daikin Industries, Ltd. | D37: Example 8 | E37: FFKM | F37: TFE/PMVE copolymer (67/33 mol%) | G37: peroxide | H37: 100 | I37: 0 | J37: 0 | K37: 0 | L37: 0 | M37: 0 | N37: 0 | O37: 0 | P37: 0 | Q37: 1 | R37: 2 | S37: 0 | T37: 0 | U37: 0 | V37: 0 | W37: 65 | X37: 13.73 | Y37: 210 | Z37: 2.94 | AD37: =I37+J37+K37+L37+M37+N37+O37+P37 | AE37: 1 | AF37: 1 | AG37: 1 | AH37: 1 | AI37: 0
A38: G037 | B38: US8173727B2 | C38: Daikin Industries, Ltd. | D38: Example 9 | E38: FFKM | F38: TFE/perfluoroalkyl vinyl ether/cyano-group monomer 59.4/40.1/0.5 mol (Daikin) | G38: nitrile_other | H38: 100 | I38: 0 | J38: 0 | K38: 0 | L38: 0 | M38: 0 | N38: 0 | O38: 15 | P38: 0 | Q38: 0 | R38: 0 | S38: 1.2 | T38: 0 | U38: 0 | V38: 0 | X38: 14.42 | Y38: 335 | Z38: 2.26 | AA38: 42 | AB38: 300C x 70h, AS-568A-214 O-ring (JIS K6262) | AC38: 300 | AD38: =I38+J38+K38+L38+M38+N38+O38+P38 | AE38: 0 | AF38: 1 | AG38: 1 | AH38: 1 | AI38: 1
A39: G038 | B39: US8173727B2 | C39: Daikin Industries, Ltd. | D39: Example 10 | E39: FFKM | F39: TFE/perfluoroalkyl vinyl ether/cyano-group monomer 59.4/40.1/0.5 mol (Daikin) | G39: nitrile_other | H39: 100 | I39: 0 | J39: 0 | K39: 0 | L39: 0 | M39: 0 | N39: 0 | O39: 15 | P39: 0 | Q39: 0 | R39: 0 | S39: 1.2 | T39: 0 | U39: 0 | V39: 0 | X39: 12.85 | Z39: 2.94 | AA39: 27 | AB39: 300C x 70h, AS-568A-214 O-ring (JIS K6262) | AC39: 300 | AD39: =I39+J39+K39+L39+M39+N39+O39+P39 | AE39: 0 | AF39: 1 | AG39: 0 | AH39: 1 | AI39: 1
A40: G039 | B40: US8173727B2 | C40: Daikin Industries, Ltd. | D40: Example 11 | E40: FFKM | F40: TFE/perfluoroalkyl vinyl ether/cyano-group monomer 59.4/40.1/0.5 mol (Daikin) | G40: nitrile_other | H40: 100 | I40: 0 | J40: 0 | K40: 0 | L40: 0 | M40: 0 | N40: 0 | O40: 15 | P40: 0 | Q40: 0 | R40: 0 | S40: 1.2 | T40: 0 | U40: 0 | V40: 0 | X40: 14.91 | Y40: 288 | Z40: 2.45 | AA40: 32 | AB40: 300C x 70h, AS-568A-214 O-ring (JIS K6262) | AC40: 300 | AD40: =I40+J40+K40+L40+M40+N40+O40+P40 | AE40: 0 | AF40: 1 | AG40: 1 | AH40: 1 | AI40: 1
A41: G040 | B41: US8173727B2 | C41: Daikin Industries, Ltd. | D41: Example 12 | E41: FFKM | F41: TFE/perfluoroalkyl vinyl ether/cyano-group monomer 59.4/40.1/0.5 mol (Daikin) | G41: nitrile_other | H41: 100 | I41: 20 | J41: 0 | K41: 0 | L41: 0 | M41: 0 | N41: 0 | O41: 0 | P41: 0 | Q41: 0 | R41: 0 | S41: 0.8 | T41: 0 | U41: 0 | V41: 0 | X41: 19.52 | Y41: 273 | Z41: 5 | AA41: 38 | AB41: 300C x 70h, AS-568A-214 O-ring (JIS K6262) | AC41: 300 | AD41: =I41+J41+K41+L41+M41+N41+O41+P41 | AE41: 0 | AF41: 1 | AG41: 1 | AH41: 1 | AI41: 1
A42: G041 | B42: US8173727B2 | C42: Daikin Industries, Ltd. | D42: Example 13 | E42: FFKM | F42: TFE/perfluoroalkyl vinyl ether/cyano-group monomer 59.4/40.1/0.5 mol (Daikin) | G42: nitrile_other | H42: 100 | I42: 0 | J42: 15 | K42: 0 | L42: 0 | M42: 0 | N42: 0 | O42: 0 | P42: 0 | Q42: 0 | R42: 0 | S42: 1.2 | T42: 0 | U42: 0 | V42: 0 | X42: 13.34 | Y42: 275 | Z42: 4.9 | AB42: 300C x 70h, AS-568A-214 O-ring (JIS K6262) | AC42: 300 | AD42: =I42+J42+K42+L42+M42+N42+O42+P42 | AE42: 0 | AF42: 1 | AG42: 1 | AH42: 1 | AI42: 0
A43: G042 | B43: US8173727B2 | C43: Daikin Industries, Ltd. | D43: Example 14 | E43: FFKM | F43: TFE/perfluoroalkyl vinyl ether/cyano-group monomer 59.4/40.1/0.5 mol (Daikin) | G43: nitrile_other | H43: 100 | I43: 0 | J43: 0 | K43: 15 | L43: 0 | M43: 0 | N43: 0 | O43: 0 | P43: 0 | Q43: 0 | R43: 0 | S43: 1.2 | T43: 0 | U43: 0 | V43: 0 | X43: 15.79 | Y43: 307 | Z43: 2.26 | AA43: 45 | AB43: 300C x 70h, AS-568A-214 O-ring (JIS K6262) | AC43: 300 | AD43: =I43+J43+K43+L43+M43+N43+O43+P43 | AE43: 0 | AF43: 1 | AG43: 1 | AH43: 1 | AI43: 1
A44: G043 | B44: US8211964B2 | C44: Daikin Industries, Ltd. | D44: Example 2 | E44: FFKM | F44: TFE/PMVE/CNVE (CF2=CFOCF2CF(CF3)OCF2CF2CN) elastomer with cyano end groups (Preparation Example 1) | G44: nitrile_triazine | H44: 100 | I44: 0 | J44: 0 | K44: 0 | L44: 0 | M44: 0 | N44: 0 | O44: 0 | P44: 0 | Q44: 0 | R44: 0 | S44: 0.35 | T44: 0 | U44: 0 | V44: 0 | W44: 57.2 | X44: 9.32 | Y44: 295 | Z44: 1.18 | AA44: 18 | AB44: 200C x 72h, AS-568A-214 O-ring | AC44: 200 | AD44: =I44+J44+K44+L44+M44+N44+O44+P44 | AE44: 1 | AF44: 1 | AG44: 1 | AH44: 1 | AI44: 1
A45: G044 | B45: US8211964B2 | C45: Daikin Industries, Ltd. | D45: Example 3 | E45: FFKM | F45: TFE/PMVE/CNVE (CF2=CFOCF2CF(CF3)OCF2CF2CN) elastomer with cyano end groups (Preparation Example 1) | G45: nitrile_triazine | H45: 100 | I45: 0 | J45: 0 | K45: 0 | L45: 0 | M45: 0 | N45: 0 | O45: 0 | P45: 0 | Q45: 0 | R45: 0 | S45: 0.4 | T45: 0 | U45: 0 | V45: 0 | W45: 58 | X45: 10 | Y45: 265 | Z45: 1.37 | AA45: 17 | AB45: 200C x 72h, AS-568A-214 O-ring | AC45: 200 | AD45: =I45+J45+K45+L45+M45+N45+O45+P45 | AE45: 1 | AF45: 1 | AG45: 1 | AH45: 1 | AI45: 1
